2023-10-25 18:52:28,138 INFO    StreamThr :2643873 [internal.py:wandb_internal():86] W&B internal server running at pid: 2643873, started at: 2023-10-25 18:52:28.137815
2023-10-25 18:52:28,141 DEBUG   HandlerThread:2643873 [handler.py:handle_request():146] handle_request: status
2023-10-25 18:52:28,143 INFO    WriterThread:2643873 [datastore.py:open_for_write():85] open: /data/yli927/LM-profiling/wandb/run-20231025_185228-1femb565/run-1femb565.wandb
2023-10-25 18:52:28,144 DEBUG   SenderThread:2643873 [sender.py:send():380] send: header
2023-10-25 18:52:28,148 DEBUG   SenderThread:2643873 [sender.py:send():380] send: run
2023-10-25 18:52:31,589 INFO    SenderThread:2643873 [retry.py:__call__():172] Retry attempt failed:
Traceback (most recent call last):
  File "/home/yli927/anaconda3/envs/py3.10/lib/python3.10/site-packages/urllib3/connection.py", line 203, in _new_conn
    sock = connection.create_connection(
  File "/home/yli927/anaconda3/envs/py3.10/lib/python3.10/site-packages/urllib3/util/connection.py", line 60, in create_connection
    for res in socket.getaddrinfo(host, port, family, socket.SOCK_STREAM):
  File "/home/yli927/anaconda3/envs/py3.10/lib/python3.10/socket.py", line 955, in getaddrinfo
    for res in _socket.getaddrinfo(host, port, family, type, proto, flags):
socket.gaierror: [Errno -2] Name or service not known

The above exception was the direct cause of the following exception:

Traceback (most recent call last):
  File "/home/yli927/anaconda3/envs/py3.10/lib/python3.10/site-packages/urllib3/connectionpool.py", line 790, in urlopen
    response = self._make_request(
  File "/home/yli927/anaconda3/envs/py3.10/lib/python3.10/site-packages/urllib3/connectionpool.py", line 496, in _make_request
    conn.request(
  File "/home/yli927/anaconda3/envs/py3.10/lib/python3.10/site-packages/urllib3/connection.py", line 395, in request
    self.endheaders()
  File "/home/yli927/anaconda3/envs/py3.10/lib/python3.10/http/client.py", line 1277, in endheaders
    self._send_output(message_body, encode_chunked=encode_chunked)
  File "/home/yli927/anaconda3/envs/py3.10/lib/python3.10/http/client.py", line 1037, in _send_output
    self.send(msg)
  File "/home/yli927/anaconda3/envs/py3.10/lib/python3.10/http/client.py", line 975, in send
    self.connect()
  File "/home/yli927/anaconda3/envs/py3.10/lib/python3.10/site-packages/urllib3/connection.py", line 243, in connect
    self.sock = self._new_conn()
  File "/home/yli927/anaconda3/envs/py3.10/lib/python3.10/site-packages/urllib3/connection.py", line 210, in _new_conn
    raise NameResolutionError(self.host, self, e) from e
urllib3.exceptions.NameResolutionError: <urllib3.connection.HTTPConnection object at 0x7f94e85ce530>: Failed to resolve 'wandb.your-shared-local-host.com' ([Errno -2] Name or service not known)

The above exception was the direct cause of the following exception:

Traceback (most recent call last):
  File "/home/yli927/anaconda3/envs/py3.10/lib/python3.10/site-packages/requests/adapters.py", line 486, in send
    resp = conn.urlopen(
  File "/home/yli927/anaconda3/envs/py3.10/lib/python3.10/site-packages/urllib3/connectionpool.py", line 844, in urlopen
    retries = retries.increment(
  File "/home/yli927/anaconda3/envs/py3.10/lib/python3.10/site-packages/urllib3/util/retry.py", line 515, in increment
    raise MaxRetryError(_pool, url, reason) from reason  # type: ignore[arg-type]
urllib3.exceptions.MaxRetryError: HTTPConnectionPool(host='wandb.your-shared-local-host.com', port=80): Max retries exceeded with url: /graphql (Caused by NameResolutionError("<urllib3.connection.HTTPConnection object at 0x7f94e85ce530>: Failed to resolve 'wandb.your-shared-local-host.com' ([Errno -2] Name or service not known)"))

During handling of the above exception, another exception occurred:

Traceback (most recent call last):
  File "/home/yli927/anaconda3/envs/py3.10/lib/python3.10/site-packages/wandb/sdk/lib/retry.py", line 131, in __call__
    result = self._call_fn(*args, **kwargs)
  File "/home/yli927/anaconda3/envs/py3.10/lib/python3.10/site-packages/wandb/sdk/internal/internal_api.py", line 366, in execute
    return self.client.execute(*args, **kwargs)  # type: ignore
  File "/home/yli927/anaconda3/envs/py3.10/lib/python3.10/site-packages/wandb/vendor/gql-0.2.0/wandb_gql/client.py", line 52, in execute
    result = self._get_result(document, *args, **kwargs)
  File "/home/yli927/anaconda3/envs/py3.10/lib/python3.10/site-packages/wandb/vendor/gql-0.2.0/wandb_gql/client.py", line 60, in _get_result
    return self.transport.execute(document, *args, **kwargs)
  File "/home/yli927/anaconda3/envs/py3.10/lib/python3.10/site-packages/wandb/sdk/lib/gql_request.py", line 58, in execute
    request = self.session.post(self.url, **post_args)
  File "/home/yli927/anaconda3/envs/py3.10/lib/python3.10/site-packages/requests/sessions.py", line 637, in post
    return self.request("POST", url, data=data, json=json, **kwargs)
  File "/home/yli927/anaconda3/envs/py3.10/lib/python3.10/site-packages/requests/sessions.py", line 589, in request
    resp = self.send(prep, **send_kwargs)
  File "/home/yli927/anaconda3/envs/py3.10/lib/python3.10/site-packages/requests/sessions.py", line 703, in send
    r = adapter.send(request, **kwargs)
  File "/home/yli927/anaconda3/envs/py3.10/lib/python3.10/site-packages/requests/adapters.py", line 519, in send
    raise ConnectionError(e, request=request)
requests.exceptions.ConnectionError: HTTPConnectionPool(host='wandb.your-shared-local-host.com', port=80): Max retries exceeded with url: /graphql (Caused by NameResolutionError("<urllib3.connection.HTTPConnection object at 0x7f94e85ce530>: Failed to resolve 'wandb.your-shared-local-host.com' ([Errno -2] Name or service not known)"))
2023-10-25 18:52:33,150 DEBUG   HandlerThread:2643873 [handler.py:handle_request():146] handle_request: keepalive
2023-10-25 18:52:38,151 DEBUG   HandlerThread:2643873 [handler.py:handle_request():146] handle_request: keepalive
2023-10-25 18:52:40,782 DEBUG   HandlerThread:2643873 [handler.py:handle_request():146] handle_request: shutdown
2023-10-25 18:52:40,783 INFO    HandlerThread:2643873 [handler.py:finish():866] shutting down handler
2023-10-25 18:52:41,150 INFO    WriterThread:2643873 [datastore.py:close():294] close: /data/yli927/LM-profiling/wandb/run-20231025_185228-1femb565/run-1femb565.wandb
